Workbook

Sheet data
A1: center_id | B1: center_name | C1: center_island
A2: 3 | B2: Shamrock - Pagbilao | C2: =VLOOKUP(A2, island!$A:$C, 3, 0) -> Luzon
A3: 26 | B3: Rav-F - Pagadian | C3: =VLOOKUP(A3, island!$A:$C, 3, 0) -> Mindanao
A4: 27 | B4: Ink ni Juan – Antimonan | C4: =VLOOKUP(A4, island!$A:$C, 3, 0) -> Luzon
A5: 31 | B5: E Core – Pagbilao | C5: =VLOOKUP(A5, island!$A:$C, 3, 0) -> Luzon
A6: 34 | B6: Thinker Thoughts - Naga City | C6: =VLOOKUP(A6, island!$A:$C, 3, 0) -> Luzon
A7: 41 | B7: Ryzen's Hub 3 - Pagadian | C7: =VLOOKUP(A7, island!$A:$C, 3, 0) -> Mindanao
A8: 47 | B8: Celine Via - Roxas City | C8: =VLOOKUP(A8, island!$A:$C, 3, 0) -> Visayas
A9: 53 | B9: WINSYLAV - Lucena | C9: =VLOOKUP(A9, island!$A:$C, 3, 0) -> Luzon
A10: 60 | B10: Reyna's Training Center - Pagadian City | C10: =VLOOKUP(A10, island!$A:$C, 3, 0) -> Mindanao
A11: 62 | B11: Sophie J - Valencia City | C11: =VLOOKUP(A11, island!$A:$C, 3, 0) -> Mindanao
A12: 66 | B12: WeTalk - Zamboanga City | C12: =VLOOKUP(A12, island!$A:$C, 3, 0) -> Mindanao
A13: 82 | B13: Uno Internet - Southern Leyte | C13: =VLOOKUP(A13, island!$A:$C, 3, 0) -> Visayas
... A119: 354 | B119: VietPhil Language Academy - Kalibo | C119: =VLOOKUP(A119, island!$A:$C, 3, 0) -> Visayas

Sheet island
A1: Center Id | B1: TPCAP Center | C1: Island
A2: 2 | B2: Apeiros - Lucena | C2: Luzon
A3: 3 | B3: Shamrock - Pagbilao | C3: Luzon
A4: 22 | B4: YJJM - La Trinidad | C4: Luzon
A5: 23 | B5: Prime English - Lucena | C5: Luzon
A6: 24 | B6: AB Outsourcing - General Santos | C6: Mindanao
A7: 25 | B7: Brilliant Minds - Cebu | C7: Visayas
A8: 26 | B8: Rav-F - Pagadian | C8: Mindanao
A9: 27 | B9: Ink ni Juan – Antimonan | C9: Luzon
A10: 28 | B10: PCOET 1 – Roxas City | C10: Visayas
A11: 29 | B11: PCOET 2 – Roxas City | C11: Visayas
A12: 30 | B12: TPTOE - Lucena | C12: Luzon
A13: 31 | B13: E Core – Pagbilao | C13: Luzon
... A36: 55 | B36: PCOET 3 - Roxas City | C36: Visayas
A37: 56
A38: 57
A39: 58
A40: 59
A41: 60 | B41: Reyna's Training Center - Pagadian City | C41: Mindanao
A42: 61 | B42: MediaBiz - Carmona | C42: Luzon
A43: 62 | B43: Sophie J - Valencia City | C43: Mindanao
A44: 63 | B44: MAFC - Davao City | C44: Mindanao
A45: 64 | B45: Brilliant Minds 2 - Cebu | C45: Visayas
A46: 65 | B46: Stacey Cafe - Bulacan | C46: Luzon
A47: 66 | B47: WeTalk - Zamboanga City | C47: Mindanao
A48: 67 | B48: NJRC Technical - Pagadian City | C48: Mindanao
A49: 68 | B49: DOR Solutions - Zamboanga del Norte | C49: Mindanao
A50: 69
A51: 70 | B51: Prime English II - Sariaya | C51: Luzon
A52: 71
A53: 72
A54: 73 | B54: Airclasshub Coworking Space - Bukidnon | C54: Mindanao
A55: 74 | B55: JayComshop - Tayabas City | C55: Luzon
A56: 75
A57: 76 | B57: Oxwow Tutorial - Baguio City | C57: Luzon
A58: 77 | B58: IDream English - Iloilo City | C58: Visayas
A59: 78 | B59: Iteach86-Iloilo | C59: Visayas
A60: 79 | B60: KAEDEE'S COWORKING SPACE - Zamboanga del Sur | C60: Mindanao
A61: 80 | B61: E-Sparta Gaming | C61: Mindanao
A62: 81 | B62: 1109 Dynamics Software - Cebu | C62: Visayas
...
